<?xml version="1.0"?>
<robot name="Robo_Car" xmlns:xacro="http://www.ros.org/wiki/xacro">

<xacro:macro name="inertial_matrix" params="mass">
        <inertial>
            <mass value="${mass}" />
                <inertia ixx="100" ixy="0.0" ixz="0.0"
                        iyy="100" iyz="0.0"
                        izz="100" />
        </inertial>
</xacro:macro>


<xacro:macro name="transmission_block" params="joint_name">
	  <transmission name="tran1">
	    <type>transmission_interface/SimpleTransmission</type>
	    <joint name="${joint_name}">
	      <hardwareInterface>hardware_interface/VelocityJointInterface</hardwareInterface>
	    </joint>
	    <actuator name="${joint_name}_motor">
	      <hardwareInterface>EffortJointInterface</hardwareInterface>
	      <mechanicalReduction>1</mechanicalReduction>
	    </actuator>
	  </transmission>
</xacro:macro>
    

    <material name="Black">
        <color rgba="0.0 0.0 0.0 1.0"/>
    </material>
    <material name="White">
        <color rgba="1.0 1.0 1.0 1.0"/>
    </material>
    <material name="Yellow">
        <color rgba="1.0 1.0 0.0 1.0"/>
    </material>

    <link name="base_link">
        <visual>
            <geometry>
                <box size="5.0 2.0 1.0"/>
            </geometry>
            <origin rpy="0 0 0" xyz="0 0 1.0"/>
            <material name="Yellow"/>
        </visual>
        <collision>
            <geometry>
                <box size="5.0 1.0 0.5"/>
            </geometry>
            <origin rpy="0 0 0" xyz="0 0 1.0"/>
        </collision>
        <gazebo reference="base_link">
            <material>Gazebo/White</material>
        </gazebo>
    </link>

    <gazebo>
        <plugin name="gazebo_ros_control" filename= "libgazebo_ros_control.so">
            <robotNamespace>/</robotNamespace>
        </plugin>
    </gazebo>

</robot>


   <!-- <link name="rf_link">
        <visual>
            <geometry>
                <box size="0.5 0.1 0.1"/>
            </geometry>
            <origin rpy="0 0 0" xyz="0 0 0"/>
            <material name="White"/>
        </visual>
        <!-- <collision>
            <geometry>
                <box size="5.0 1.0 0.5"/>
            </geometry>
            <origin rpy="0 0 0" xyz="0 0 1.0"/>
        </collision> -->
        <gazebo reference="base_link">
            <material>Gazebo/White</material>
        </gazebo>
    </link>    

    <joint name="rf_joint" type="fixed">
        <parent link="base_link"/>
        <child link="rf_link"/>
	<origin rpy="0 0 0" xyz="2.5 1.0 0"/>
        <axis rpy="0  0" xyz="0 0 1"/>
        <!-- <limit effort="180" velocity="100"/> -->
        <dynamic damping="0.0" friction="0.0"/>
    </joint>

    <link name="right_front">
        <visual>
            <geometry>
                <cylinder length="0.5" radius="1.0"/>
            </geometry>
            <origin rpy="1.57 0 0" xyz="0 0 0"/>
            <material name="Black"/>
        </visual>
        <xacro:inertial_matrix mass="1"/>
        <collision>
            <geometry>
                <cylinder length="0.5" radius="1.0"/>
            </geometry>
            <origin rpy="1.57 0 0" xyz="0 0 0"/>
        </collision>
        <gazebo reference="right_front">
            <material>Black</material>
        </gazebo>
    </link>

    <joint name="right_front_joint" type="continuous">
        <parent link="rf_joint"/>
        <child link="right_front"/>
	<origin rpy="0 0 0" xyz="3.0 1.0 1.0"/>
        <axis rpy="0  0" xyz="0 0 1"/>
        <limit effort="180" velocity="100"/>
        <dynamic damping="0.0" friction="0.0"/>
    </joint>

    <link name="lf_link">
        <visual>
            <geometry>
                <box size="0.5 0.1 0.1"/>
            </geometry>
            <origin rpy="0 0 0" xyz="0 0 0"/>
            <material name="White"/>
        </visual>
        <!-- <collision>
            <geometry>
                <box size="5.0 1.0 0.5"/>
            </geometry>
            <origin rpy="0 0 0" xyz="0 0 1.0"/>
        </collision> -->
        <gazebo reference="base_link">
            <material>Gazebo/White</material>
        </gazebo>
    </link>    

    <joint name="rf_joint" type="fixed">
        <parent link="base_link"/>
        <child link="lf_link"/>
	<origin rpy="0 0 0" xyz="-2.5 1.0 0"/>
        <axis rpy="0  0" xyz="0 0 1"/>
        <!-- <limit effort="180" velocity="100"/> -->
        <dynamic damping="0.0" friction="0.0"/>
    </joint>

    <link name="left_front">
        <visual>
            <geometry>
                <cylinder length="0.5" radius="1.0"/>
            </geometry>
            <origin rpy="1.57 0 0" xyz="0 0 0"/>
            <material name="Black"/>
        </visual>
        <xacro:inertial_matrix mass="1"/>
        <collision>
            <geometry>
                <cylinder length="0.5" radius="1.0"/>
            </geometry>
            <origin rpy="1.57 0 0" xyz="0 0 0"/>
        </collision>
        <gazebo reference="left_front">
            <material>Black</material>
        </gazebo>
    </link>

    <joint name="left_front_joint" type="continuous">
        <parent link="base_link"/>
        <child link="left_front"/>
	<origin rpy="0 0 0" xyz="-3.0 1.0 1.0"/>
        <axis rpy="0  0" xyz="0 1 0"/>
        <limit effort="180" velocity="100"/>
        <dynamic damping="0.0" friction="0.0"/>
    </joint>

    <link name="rb_link">
        <visual>
            <geometry>
                <box size="0.5 0.1 0.1"/>
            </geometry>
            <origin rpy="0 0 0" xyz="0 0 0"/>
            <material name="White"/>
        </visual>
        <!-- <collision>
            <geometry>
                <box size="5.0 1.0 0.5"/>
            </geometry>
            <origin rpy="0 0 0" xyz="0 0 1.0"/>
        </collision> -->
        <gazebo reference="base_link">
            <material>Gazebo/White</material>
        </gazebo>
    </link>    

    <joint name="rb_joint" type="fixed">
        <parent link="base_link"/>
        <child link="rb_link"/>
	<origin rpy="0 0 0" xyz="2.5 -1.0 0"/>
        <axis rpy="0  0" xyz="0 0 1"/>
        <!-- <limit effort="180" velocity="100"/> -->
        <dynamic damping="0.0" friction="0.0"/>
    </joint>

    <link name="right_back">
        <visual>
            <geometry>
                <cylinder length="0.5" radius="1.0"/>
            </geometry>
            <origin rpy="1.57 0 0" xyz="0 0 0"/>
            <material name="Black"/>
        </visual>
        <xacro:inertial_matrix mass="1"/>
        <collision>
            <geometry>
                <cylinder length="0.5" radius="1.0"/>
            </geometry>
            <origin rpy="1.57 0 0" xyz="0 0 0"/>
        </collision>
        <gazebo reference="right_back">
            <material>Black</material>
        </gazebo>
    </link>

    <joint name="right_back_joint" type="continuous">
        <parent link="base_link"/>
        <child link="right_back"/>
	<origin rpy="0 0 0" xyz="3.0 -1.0 1.0"/>
        <axis rpy="0  0" xyz="0 1 0"/>
        <limit effort="180" velocity="100"/>
        <dynamic damping="0.0" friction="0.0"/>
    </joint>

    <link name="lb_link">
        <visual>
            <geometry>
                <box size="0.5 0.1 0.1"/>
            </geometry>
            <origin rpy="0 0 0" xyz="0 0 0"/>
            <material name="White"/>
        </visual>
        <!-- <collision>
            <geometry>
                <box size="5.0 1.0 0.5"/>
            </geometry>
            <origin rpy="0 0 0" xyz="0 0 1.0"/>
        </collision> -->
        <gazebo reference="base_link">
            <material>Gazebo/White</material>
        </gazebo>
    </link>    

    <joint name="lb_joint" type="fixed">
        <parent link="base_link"/>
        <child link="lb_link"/>
	<origin rpy="0 0 0" xyz="-2.5 -1.0 0"/>
        <axis rpy="0  0" xyz="0 0 1"/>
        <!-- <limit effort="180" velocity="100"/> -->
        <dynamic damping="0.0" friction="0.0"/>
    </joint>

    <link name="left_back">
        <visual>
            <geometry>
                <cylinder length="0.5" radius="1.0"/>
            </geometry>
            <origin rpy="1.57 0 0" xyz="0 0 0"/>
            <material name="Black"/>
            <xacro:inertial_matrix mass="1"/>
        <collision>
            <geometry>
                <cylinder length="0.5" radius="1.0"/>
            </geometry>
            <origin rpy="1.57 0 0" xyz="0 0 0"/>
        </collision>
        <gazebo reference="left_back">
            <material>Black</material>
        </gazebo>
        </visual>
    </link>

    <joint name="left_back_joint" type="continuous">
        <parent link="base_link"/>
        <child link="left_back"/>
	<origin rpy="0 0 0" xyz="-3.0 -1.0 1.0"/>
        <axis rpy="0  0" xyz="0 1 0"/>
        <limit effort="180" velocity="100"/>
        <dynamic damping="0.0" friction="0.0"/>
    </joint>
    
    <xacro:transmission_block joint_name="right_front_joint"/>
    <xacro:transmission_block joint_name="left_front_joint"/>
    <xacro:transmission_block joint_name="right_back_joint"/>
    <xacro:transmission_block joint_name="left_back_joint"/> -->

    <gazebo>
        <plugin name="gazebo_ros_control" filename= "libgazebo_ros_control.so">
            <robotNamespace>/</robotNamespace>
        </plugin>
    </gazebo>

</robot>


